<?xml version="1.0" ?>
<robot name="gen3n7">

  <link name="world"/>
  
  <joint name="gen3_base_joint" type="fixed" dont_collapse="true">
    <origin rpy="0 0 0" xyz="0 0 0"/>
    <parent link="world"/>
    <child link="gen3_base_link"/>
  </joint>

  <link name="gen3_base_link">
    <inertial>
      <origin rpy="0 0 0" xyz="-0.000648 -0.000166 0.084487"/>
      <mass value="1.697"/>
      <inertia ixx="0.004622" ixy="9E-06" ixz="6E-05" iyy="0.004495" iyz="9E-06" izz="0.002079"/>
    </inertial>
    <visual>
      <origin rpy="0 0 0" xyz="0 0 0"/>
      <geometry>
        <mesh filename="package://gen3n7_description/meshes/base_link.dae"/>
      </geometry>
      <material name="">
        <color rgba="0.75294 0.75294 0.75294 1"/>
      </material>
    </visual>
    <collision>
      <origin rpy="0 0 0" xyz="0 0 0"/>
      <geometry>
        <mesh filename="package://gen3n7_description/meshes/base_link.dae"/>
      </geometry>
    </collision>
  </link>

  <joint name="gen3_joint_1" type="continuous">
    <origin rpy="3.1416 2.7629E-18 -4.9305E-36" xyz="0 0 0.15643"/>
    <parent link="gen3_base_link"/>
    <child link="gen3_shoulder_link"/>
    <axis xyz="0 0 1"/>
    <limit effort="39" velocity="1.3963"/>
  </joint>

  <link name="gen3_shoulder_link">
    <inertial>
      <origin rpy="0 0 0" xyz="-2.3E-05 -0.010364 -0.07336"/>
      <mass value="1.3773"/>
      <inertia ixx="0.00457" ixy="1E-06" ixz="2E-06" iyy="0.004831" iyz="0.000448" izz="0.001409"/>
    </inertial>
    <visual>
      <origin rpy="0 0 0" xyz="0 0 0"/>
      <geometry>
        <mesh filename="package://gen3n7_description/meshes/shoulder_link.dae"/>
      </geometry>
      <material name="">
        <color rgba="0.75294 0.75294 0.75294 1"/>
      </material>
    </visual>
    <collision>
      <origin rpy="0 0 0" xyz="0 0 0"/>
      <geometry>
        <mesh filename="package://gen3n7_description/meshes/shoulder_link.dae"/>
      </geometry>
    </collision>
  </link>

  <joint name="gen3_joint_2" type="revolute">
    <origin rpy="1.5708 2.1343E-17 -1.1102E-16" xyz="0 0.005375 -0.12838"/>
    <parent link="gen3_shoulder_link"/>
    <child link="gen3_half_arm_1_link"/>
    <axis xyz="0 0 1"/>
    <limit effort="39" lower="-2.41" upper="2.41" velocity="1.3963"/>
  </joint>

  <link name="gen3_half_arm_1_link">
    <inertial>
      <origin rpy="0 0 0" xyz="-4.4E-05 -0.09958 -0.013278"/>
      <mass value="1.1636"/>
      <inertia ixx="0.011088" ixy="5E-06" ixz="0" iyy="0.001072" iyz="-0.000691" izz="0.011255"/>
    </inertial>
    <visual>
      <origin rpy="0 0 0" xyz="0 0 0"/>
      <geometry>
        <mesh filename="package://gen3n7_description/meshes/half_arm_1_link.dae"/>
      </geometry>
      <material name="">
        <color rgba="0.75294 0.75294 0.75294 1"/>
      </material>
    </visual>
    <collision>
      <origin rpy="0 0 0" xyz="0 0 0"/>
      <geometry>
        <mesh filename="package://gen3n7_description/meshes/half_arm_1_link.dae"/>
      </geometry>
    </collision>
  </link>

  <joint name="gen3_joint_3" type="continuous">
    <origin rpy="-1.5708 1.2326E-32 -2.9122E-16" xyz="0 -0.21038 -0.006375"/>
    <parent link="gen3_half_arm_1_link"/>
    <child link="gen3_half_arm_2_link"/>
    <axis xyz="0 0 1"/>
    <limit effort="39" velocity="1.3963"/>
  </joint>

  <link name="gen3_half_arm_2_link">
    <inertial>
      <origin rpy="0 0 0" xyz="-4.4E-05 -0.006641 -0.117892"/>
      <mass value="1.1636"/>
      <inertia ixx="0.010932" ixy="0" ixz="-7E-06" iyy="0.011127" iyz="0.000606" izz="0.001043"/>
    </inertial>
    <visual>
      <origin rpy="0 0 0" xyz="0 0 0"/>
      <geometry>
        <mesh filename="package://gen3n7_description/meshes/half_arm_2_link.dae"/>
      </geometry>
      <material name="">
        <color rgba="0.75294 0.75294 0.75294 1"/>
      </material>
    </visual>
    <collision>
      <origin rpy="0 0 0" xyz="0 0 0"/>
      <geometry>
        <mesh filename="package://gen3n7_description/meshes/half_arm_2_link.dae"/>
      </geometry>
    </collision>
  </link>

  <joint name="gen3_joint_4" type="revolute">
    <origin rpy="1.5708 -6.6954E-17 -1.6653E-16" xyz="0 0.006375 -0.21038"/>
    <parent link="gen3_half_arm_2_link"/>
    <child link="gen3_forearm_link"/>
    <axis xyz="0 0 1"/>
    <limit effort="39" lower="-2.66" upper="2.66" velocity="1.3963"/>
  </joint>

  <link name="gen3_forearm_link">
    <inertial>
      <origin rpy="0 0 0" xyz="-1.8E-05 -0.075478 -0.015006"/>
      <mass value="0.9302"/>
      <inertia ixx="0.008147" ixy="-1E-06" ixz="0" iyy="0.000631" iyz="-0.0005" izz="0.008316"/>
    </inertial>
    <visual>
      <origin rpy="0 0 0" xyz="0 0 0"/>
      <geometry>
        <mesh filename="package://gen3n7_description/meshes/forearm_link.dae"/>
      </geometry>
      <material name="">
        <color rgba="0.75294 0.75294 0.75294 1"/>
      </material>
    </visual>
    <collision>
      <origin rpy="0 0 0" xyz="0 0 0"/>
      <geometry>
        <mesh filename="package://gen3n7_description/meshes/forearm_link.dae"/>
      </geometry>
    </collision>
  </link>

  <joint name="gen3_joint_5" type="continuous">
    <origin rpy="-1.5708 2.2204E-16 -6.373E-17" xyz="0 -0.20843 -0.006375"/>
    <parent link="gen3_forearm_link"/>
    <child link="gen3_spherical_wrist_1_link"/>
    <axis xyz="0 0 1"/>
    <limit effort="9" velocity="1.2218"/>
  </joint>

  <link name="gen3_spherical_wrist_1_link">
    <inertial>
      <origin rpy="0 0 0" xyz="1E-06 -0.009432 -0.063883"/>
      <mass value="0.6781"/>
      <inertia ixx="0.001596" ixy="0" ixz="0" iyy="0.001607" iyz="0.000256" izz="0.000399"/>
    </inertial>
    <visual>
      <origin rpy="0 0 0" xyz="0 0 0"/>
      <geometry>
        <mesh filename="package://gen3n7_description/meshes/spherical_wrist_1_link.dae"/>
      </geometry>
      <material name="">
        <color rgba="0.75294 0.75294 0.75294 1"/>
      </material>
    </visual>
    <collision>
      <origin rpy="0 0 0" xyz="0 0 0"/>
      <geometry>
        <mesh filename="package://gen3n7_description/meshes/spherical_wrist_1_link.dae"/>
      </geometry>
    </collision>
  </link>

  <joint name="gen3_joint_6" type="revolute">
    <origin rpy="1.5708 9.2076E-28 -8.2157E-15" xyz="0 0.00017505 -0.10593"/>
    <parent link="gen3_spherical_wrist_1_link"/>
    <child link="gen3_spherical_wrist_2_link"/>
    <axis xyz="0 0 1"/>
    <limit effort="9" lower="-2.23" upper="2.23" velocity="1.2218"/>
  </joint>

  <link name="gen3_spherical_wrist_2_link">
    <inertial>
      <origin rpy="0 0 0" xyz="1E-06 -0.045483 -0.00965"/>
      <mass value="0.6781"/>
      <inertia ixx="0.001641" ixy="0" ixz="0" iyy="0.00041" iyz="-0.000278" izz="0.001641"/>
    </inertial>
    <visual>
      <origin rpy="0 0 0" xyz="0 0 0"/>
      <geometry>
        <mesh filename="package://gen3n7_description/meshes/spherical_wrist_2_link.dae"/>
      </geometry>
      <material name="">
        <color rgba="0.75294 0.75294 0.75294 1"/>
      </material>
    </visual>
    <collision>
      <origin rpy="0 0 0" xyz="0 0 0"/>
      <geometry>
        <mesh filename="package://gen3n7_description/meshes/spherical_wrist_2_link.dae"/>
      </geometry>
    </collision>
  </link>
  
  <joint name="gen3_joint_7" type="continuous">
    <origin rpy="-1.5708 -5.5511E-17 9.6396E-17" xyz="0 -0.10593 -0.00017505"/>
    <parent link="gen3_spherical_wrist_2_link"/>
    <child link="gen3_bracelet_link"/>
    <axis xyz="0 0 1"/>
    <limit effort="9" velocity="1.2218"/>
  </joint>

  <link name="gen3_bracelet_link">
    <inertial>
      <origin rpy="0 0 0" xyz="-9.3E-05 0.000132 -0.022905"/>
      <mass value="0.364"/>
      <inertia ixx="0.000214" ixy="0" ixz="1E-06" iyy="0.000223" iyz="-2E-06" izz="0.00024"/>
    </inertial>
    <visual>
      <origin rpy="0 0 0" xyz="0 0 0"/>
      <geometry>
        <mesh filename="package://gen3n7_description/meshes/bracelet_no_vision_link.dae"/>
      </geometry>
      <material name="">
        <color rgba="0.75294 0.75294 0.75294 1"/>
      </material>
    </visual>
    <collision>
      <origin rpy="0 0 0" xyz="0 0 0"/>
      <geometry>
        <mesh filename="package://gen3n7_description/meshes/bracelet_no_vision_link.dae"/>
      </geometry>
    </collision>
  </link>
  
  <joint name="gen3_end_effector" type="fixed" dont_collapse="true">
    <origin rpy="3.14159265358979 1.09937075168372E-32 0" xyz="0 0 -0.0615250000000001"/>
    <parent link="gen3_bracelet_link"/>
    <child link="gen3_end_effector_link"/>
    <axis xyz="0 0 0"/>
  </joint>

  <link name="gen3_end_effector_link"/>

  <!--################################################
  #####                Robotiq                   #####
  ####################################################-->

  <joint name="robotiq_85_base_joint" type="fixed" dont_collapse="true">
    <parent link="gen3_end_effector_link"/>
    <child link="robotiq_arg2f_base_link"/>
    <origin rpy="0 0 0" xyz="0 0 0"/>
  </joint>

  <link name="robotiq_arg2f_base_link">
  <inertial>
      <origin rpy="0 0 0" xyz="8.625E-08 -4.6583E-06 0.03145"/>
      <mass value="0.22652"/>
      <inertia ixx="0.00020005" ixy="-4.2442E-10" ixz="-2.9069E-10" iyy="0.00017832" iyz="-3.4402E-08" izz="0.00013478"/>
  </inertial>
  <visual>
      <origin rpy="0 0 0" xyz="0 0 0"/>
      <geometry>
      <mesh filename="package://gen3n7_description/meshes/robotiq_85/visual/robotiq_arg2f_85_base_link.dae" scale="0.001 0.001 0.001"/>
      </geometry>
      <material name="LightGrey">
      <color rgba="0.7 0.7 0.7 1.0"/>
      </material>
  </visual>
  <collision>
      <origin rpy="0 0 0" xyz="0 0 0"/>
      <geometry>
      <mesh filename="package://gen3n7_description/meshes/robotiq_85/collision/robotiq_arg2f_base_link.stl"/>
      </geometry>
  </collision>
  </link>

  <joint name="finger_joint" type="revolute">
      <origin rpy="0 0 3.14159265359" xyz="0 -0.0306011 0.054904"/>
      <parent link="robotiq_arg2f_base_link"/>
      <child link="left_outer_knuckle"/>
      <axis xyz="1 0 0"/>
      <limit effort="1000" lower="0" upper="0.8" velocity="2.0"/>
  </joint>

  <link name="left_outer_knuckle">
  <inertial>
      <origin xyz="-0.000200000000003065 0.0199435877845359 0.0292245259211331" rpy="0 0 0" />
      <mass value="0.00853198276973456" />
      <inertia ixx="2.89328108496468E-06" ixy="-1.57935047237397E-19" ixz="-1.93980378593255E-19" iyy="1.86719750325683E-06" iyz="-1.21858577871576E-06" izz="1.21905238907251E-06" />
      </inertial>
  <visual>
      <origin rpy="0 0 0" xyz="0 0 0"/>
      <geometry>
      <mesh filename="package://gen3n7_description/meshes/robotiq_85/visual/robotiq_arg2f_85_outer_knuckle.dae" scale="0.001 0.001 0.001"/>
      </geometry>
      <material name="">
      <color rgba="1 1 0 1"/>
      </material>
  </visual>
  <collision>
      <origin rpy="0 0 0" xyz="0 0 0"/>
      <geometry>
      <mesh filename="package://gen3n7_description/meshes/robotiq_85/collision/robotiq_arg2f_85_outer_knuckle.dae" scale="0.001 0.001 0.001"/>
      </geometry>
  </collision>
  </link>

  <joint name="left_outer_finger_joint" type="fixed" dont_collapse="true">
      <origin rpy="0 0 0" xyz="0 0.0315 -0.0041"/>
      <parent link="left_outer_knuckle"/>
      <child link="left_outer_finger"/>
      <axis xyz="1 0 0"/>
  </joint>

  <link name="left_outer_finger">
  <inertial>
      <origin xyz="0.00030115855001899 0.0373907951953854 -0.0208027427000385" rpy="0 0 0" />
      <mass value="0.022614240507152" />
      <inertia ixx="1.52518312458174E-05" ixy="9.76583423954399E-10" ixz="-5.43838577022588E-10" iyy="6.17694243867776E-06" iyz="6.78636130740228E-06" izz="1.16494917907219E-05" />
      </inertial>
  <visual>
      <origin rpy="0 0 0" xyz="0 0 0"/>
      <geometry>
      <mesh filename="package://gen3n7_description/meshes/robotiq_85/visual/robotiq_arg2f_85_outer_finger.dae" scale="0.001 0.001 0.001"/>
      </geometry>
      <material name="LightGrey">
      <color rgba="0 1 1 1.0"/>
      </material>
  </visual>
  <collision>
      <origin rpy="0 0 0" xyz="0 0 0"/>
      <geometry>
      <mesh filename="package://gen3n7_description/meshes/robotiq_85/collision/robotiq_arg2f_85_outer_finger.dae" scale="0.001 0.001 0.001"/>
      </geometry>
  </collision>
  </link>

  <joint name="left_inner_finger_joint" type="revolute">
      <origin rpy="0 0 0" xyz="0 0.0061 0.0471"/>
      <parent link="left_outer_finger"/>
      <child link="left_inner_finger"/>
      <axis xyz="1 0 0"/>
      <limit effort="1000" lower="-0.8757" upper="0" velocity="2.0"/>
      <mimic joint="finger_joint" multiplier="-1" offset="0"/>
  </joint>

  <link name="left_inner_finger">
  <inertial>
      <origin xyz="0.000299999999999317 0.0160078233491243 -0.0136945669206257" rpy="0 0 0" />
      <mass value="0.0104003125914103" />
      <inertia ixx="2.71909453810972E-06" ixy="1.35402465472579E-21" ixz="-7.1817349065269E-22" iyy="7.69100314106116E-07" iyz="6.74715432769696E-07" izz="2.30315190420171E-06" />
      </inertial>
  <visual>
      <origin rpy="0 0 0" xyz="0 0 0"/>
      <geometry>
      <mesh filename="package://gen3n7_description/meshes/robotiq_85/visual/robotiq_arg2f_85_inner_finger.dae" scale="0.001 0.001 0.001"/>
      </geometry>
      <material name="LightGrey">
      <color rgba="1 0 1 1.0"/>
      </material>
  </visual>
  <collision>
      <origin rpy="0 0 0" xyz="0 0 0"/>
      <geometry>
      <mesh filename="package://gen3n7_description/meshes/robotiq_85/collision/robotiq_arg2f_85_inner_finger.dae" scale="0.001 0.001 0.001"/>
      </geometry>
  </collision>
  </link>

  <joint name="left_inner_finger_pad_joint" type="fixed" dont_collapse="true">
      <origin rpy="0 0 0" xyz="0 -0.0220203446692936 0.03242"/>
      <parent link="left_inner_finger"/>
      <child link="left_inner_finger_pad"/>
      <axis xyz="0 0 1"/>
  </joint>

  <link name="left_inner_finger_pad">
  <inertial>
      <mass value="1."/>
      <inertia ixx="1E-10" ixy="1E-10" ixz="1E-10" iyy="1E-10" iyz="1E-10" izz="1E-10"/>
  </inertial>
  <visual>
      <origin rpy="0 0 0" xyz="0 0 0"/>
      <geometry>
      <box size="0.022 0.00635 0.0375"/>
      </geometry>
      <material name="UR-Blue">
      <color rgba="0.376 0.576 0.674 1.0"/>
      </material>
  </visual>
  <collision>
      <origin rpy="0 0 0" xyz="0 0 0"/>
      <geometry>
      <box size="0.022 0.00635 0.0375"/>
      </geometry>
              <surface>
      <friction>
      <ode>
          <mu1>100000.0</mu1>
          <mu2>100000.0</mu2>
      </ode>
      </friction>
      <contact>
      <ode>
          <kp>1e+5</kp>
          <kd>1</kd>
          <soft_cfm>0</soft_cfm>
          <soft_erp>0.2</soft_erp>
          <minDepth>0.002</minDepth>
          <maxVel>0</maxVel>
      </ode>
      </contact>
      </surface>
      <material name="">
      <color rgba="0.9 0.0 0.0 1"/>
      </material>
  </collision>
  </link>

  <joint name="left_inner_knuckle_joint" type="revolute">
      <origin rpy="0 0 3.14159265359" xyz="0 -0.0127 0.06142"/>
      <parent link="robotiq_arg2f_base_link"/>
      <child link="left_inner_knuckle"/>
      <axis xyz="1 0 0"/>
      <limit effort="1000" lower="0" upper="0.8757" velocity="2.0"/>
      <mimic joint="finger_joint" multiplier="1" offset="0"/>
  </joint>

  <link name="left_inner_knuckle">
  <inertial>
      <origin xyz="0.000123011831763771 0.0507850843201817 0.00103968640075166" rpy="0 0 0" />
      <mass value="0.0271177346495152" />
      <inertia ixx="2.61910379223783E-05" ixy="-2.43616858946494E-07" ixz="-6.37789906117123E-09" iyy="2.8270243746167E-06" iyz="-5.37200748039765E-07" izz="2.83695868220296E-05" />
      </inertial>
  <visual>
      <origin rpy="0 0 0" xyz="0 0 0"/>
      <geometry>
      <mesh filename="package://gen3n7_description/meshes/robotiq_85/visual/robotiq_arg2f_85_inner_knuckle.dae" scale="0.001 0.001 0.001"/>
      </geometry>
      <material name="LightGrey">
      <color rgba="0 0 1 1.0"/>
      </material>
  </visual>
  <collision>
      <origin rpy="0 0 0" xyz="0 0 0"/>
      <geometry>
      <mesh filename="package://gen3n7_description/meshes/robotiq_85/collision/robotiq_arg2f_85_inner_knuckle.dae" scale="0.001 0.001 0.001"/>
      </geometry>
  </collision>
  </link>

  <joint name="right_outer_knuckle_joint" type="revolute">
      <origin rpy="0 0 0" xyz="0 0.0306011 0.054904"/>
      <parent link="robotiq_arg2f_base_link"/>
      <child link="right_outer_knuckle"/>
      <axis xyz="1 0 0"/>
      <limit effort="1000" lower="0" upper="0.81" velocity="2.0"/>
      <mimic joint="finger_joint" multiplier="1" offset="0"/>
  </joint>

  <link name="right_outer_knuckle">
  <inertial>
      <origin xyz="-0.000200000000003065 0.0199435877845359 0.0292245259211331" rpy="0 0 0" />
      <mass value="0.00853198276973456" />
      <inertia ixx="2.89328108496468E-06" ixy="-1.57935047237397E-19" ixz="-1.93980378593255E-19" iyy="1.86719750325683E-06" iyz="-1.21858577871576E-06" izz="1.21905238907251E-06" />
      </inertial>
  <visual>
  <origin rpy="0 0 0" xyz="0 0 0"/>
  <geometry>
      <mesh filename="package://gen3n7_description/meshes/robotiq_85/visual/robotiq_arg2f_85_outer_knuckle.dae" scale="0.001 0.001 0.001"/>
  </geometry>
  <material name="">
      <color rgba="0.792156862745098 0.819607843137255 0.933333333333333 1"/>
  </material>
  </visual>
  <collision>
  <origin rpy="0 0 0" xyz="0 0 0"/>
  <geometry>
      <mesh filename="package://gen3n7_description/meshes/robotiq_85/collision/robotiq_arg2f_85_outer_knuckle.dae" scale="0.001 0.001 0.001"/>
  </geometry>
  </collision>
  </link>

  <joint name="right_outer_finger_joint" type="fixed" dont_collapse="true">
      <origin rpy="0 0 0" xyz="0 0.0315 -0.0041"/>
      <parent link="right_outer_knuckle"/>
      <child link="right_outer_finger"/>
      <axis xyz="1 0 0"/>
  </joint>

  <link name="right_outer_finger">
  <inertial>
      <origin xyz="0.00030115855001899 0.0373907951953854 -0.0208027427000385" rpy="0 0 0" />
      <mass value="0.022614240507152" />
      <inertia ixx="1.52518312458174E-05" ixy="9.76583423954399E-10" ixz="-5.43838577022588E-10" iyy="6.17694243867776E-06" iyz="6.78636130740228E-06" izz="1.16494917907219E-05" />
      </inertial>
  <visual>
      <origin rpy="0 0 0" xyz="0 0 0"/>
      <geometry>
      <mesh filename="package://gen3n7_description/meshes/robotiq_85/visual/robotiq_arg2f_85_outer_finger.dae" scale="0.001 0.001 0.001"/>
      </geometry>
      <material name="LightGrey">
      <color rgba="0.7 0.7 0.7 1.0"/>
      </material>
  </visual>
  <collision>
      <origin rpy="0 0 0" xyz="0 0 0"/>
      <geometry>
      <mesh filename="package://gen3n7_description/meshes/robotiq_85/collision/robotiq_arg2f_85_outer_finger.dae" scale="0.001 0.001 0.001"/>
      </geometry>
  </collision>
  </link>

  <joint name="right_inner_finger_joint" type="revolute">
      <origin rpy="0 0 0" xyz="0 0.0061 0.0471"/>
      <parent link="right_outer_finger"/>
      <child link="right_inner_finger"/>
      <axis xyz="1 0 0"/>
      <limit effort="1000" lower="-0.8757" upper="0" velocity="2.0"/>
      <mimic joint="finger_joint" multiplier="-1" offset="0"/>
  </joint>

  <link name="right_inner_finger">
  <inertial>
      <origin xyz="0.000299999999999317 0.0160078233491243 -0.0136945669206257" rpy="0 0 0" />
      <mass value="0.0104003125914103" />
      <inertia ixx="2.71909453810972E-06" ixy="1.35402465472579E-21" ixz="-7.1817349065269E-22" iyy="7.69100314106116E-07" iyz="6.74715432769696E-07" izz="2.30315190420171E-06" />
      </inertial>
  <visual>
      <origin rpy="0 0 0" xyz="0 0 0"/>
      <geometry>
      <mesh filename="package://gen3n7_description/meshes/robotiq_85/visual/robotiq_arg2f_85_inner_finger.dae" scale="0.001 0.001 0.001"/>
      </geometry>
      <material name="">
      <color rgba="0.1 0.1 0.1 1"/>
      </material>
  </visual>
  <collision>
      <origin rpy="0 0 0" xyz="0 0 0"/>
      <geometry>
      <mesh filename="package://gen3n7_description/meshes/robotiq_85/collision/robotiq_arg2f_85_inner_finger.dae" scale="0.001 0.001 0.001"/>
      </geometry>
  </collision>
  </link>

  <joint name="right_inner_finger_pad_joint" type="fixed" dont_collapse="true">
      <origin rpy="0 0 0" xyz="0 -0.0220203446692936 0.03242"/>
      <parent link="right_inner_finger"/>
      <child link="right_inner_finger_pad"/>
      <axis xyz="0 0 1"/>
  </joint>

  <link name="right_inner_finger_pad">
  <inertial>
      <mass value="1"/>
      <inertia ixx="1E-10" ixy="1E-10" ixz="1E-10" iyy="1E-10" iyz="1E-10" izz="1E-10"/>
  </inertial>
  <visual>
      <origin rpy="0 0 0" xyz="0 0 0"/>
      <geometry>
      <box size="0.022 0.00635 0.0375"/>
      </geometry>
      <material name="UR-Blue">
      <color rgba="0.376 0.576 0.674 1.0"/>
      </material>
  </visual>
  <collision>
      <origin rpy="0 0 0" xyz="0 0 0"/>
      <geometry>
      <box size="0.022 0.00635 0.0375"/>
      </geometry>
      <surface>
      <friction>
      <ode>
          <mu1>100000.0</mu1>
          <mu2>100000.0</mu2>
      </ode>
      </friction>
      <contact>
      <ode>
          <kp>1e+5</kp>
          <kd>1</kd>
          <soft_cfm>0</soft_cfm>
          <soft_erp>0.2</soft_erp>
          <minDepth>0.002</minDepth>
          <maxVel>0</maxVel>
      </ode>
      </contact>
      </surface>
      <material name="LightGrey">
      <color rgba="0.7 0.7 0.7 1.0"/>
      </material>
  </collision>
  </link>

  <joint name="right_inner_knuckle_joint" type="revolute">
      <origin rpy="0 0 0.0" xyz="0 0.0127 0.06142"/>
      <parent link="robotiq_arg2f_base_link"/>
      <child link="right_inner_knuckle"/>
      <axis xyz="1 0 0"/>
      <limit effort="1000" lower="0" upper="0.8757" velocity="2.0"/>
      <mimic joint="finger_joint" multiplier="1" offset="0"/>
  </joint>

  <link name="right_inner_knuckle">
  <inertial>
      <origin xyz="0.000123011831763771 0.0507850843201817 0.00103968640075166" rpy="0 0 0" />
      <mass value="0.0271177346495152" />
      <inertia ixx="2.61910379223783E-05" ixy="-2.43616858946494E-07" ixz="-6.37789906117123E-09" iyy="2.8270243746167E-06" iyz="-5.37200748039765E-07" izz="2.83695868220296E-05" />
      </inertial>
  <visual>
      <origin rpy="0 0 0" xyz="0 0 0"/>
      <geometry>
      <mesh filename="package://gen3n7_description/meshes/robotiq_85/visual/robotiq_arg2f_85_inner_knuckle.dae" scale="0.001 0.001 0.001"/>
      </geometry>
      <material name="LightGrey">
      <color rgba="0.7 0.7 0.7 1.0"/>
      </material>
  </visual>
  <collision>
      <origin rpy="0 0 0" xyz="0 0 0"/>
      <geometry>
      <mesh filename="package://gen3n7_description/meshes/robotiq_85/collision/robotiq_arg2f_85_inner_knuckle.dae" scale="0.001 0.001 0.001"/>
      </geometry>
  </collision>
  </link>
  
</robot>